## 自定义错误

使用`errors.New`和`panic`函数

`errors.New("错误说明")`, 会返回一个`error`类型的值, 表示一个错误.

`panic`函数, 接收一个`interface{}`类型的值(也就是任何值了)作为参数, 可以接收`error`类型的变量, 输出错误信息, 并退出程序.

```go
func error2() (err error) {

	num1 := 100
	num2 := 0
	if num2 != 0 {
		res := num1 / num2
		fmt.Println(res)
		return nil
	}else {
		return errors.New("除数不能为0")
	}

}

func main() {
	a := error2()
	fmt.Println(a)
}
```