如果抛出了一个异常，try语句中的脚本将会停止执行，然后马上转向执行catch语句中的脚本。

如果异常抛出了却没有被捕捉到，就会产生一个`fatal error`

```php

try {
        $error = 'Always throw this error';
        throw new Exception($error);

        // Code following an exception is not executed.
        // return 'Never executed';
    } catch (Exception $e) {
        return 'Caught exception: ' . $e->getMessage() . "\n";

    } finally {
        return "Second finally.\n";
    }

```

**try 中 return 后 finally 会继续执行，如果 finally 中也有return，则最终返回值为 finally 中 return 的值。**